Workbook
Name _bdm.FastTrackBookmark.1_11_2024_10_14_49_AM.edm: #REF!
Name _bdm.FastTrackBookmark.1_14_2019_9_35_13_AM.edm: #REF!
Name _bdm.FastTrackBookmark.1_14_2019_9_35_13_AM.edm: #REF!
Name _bdm.FastTrackBookmark.1_14_2019_9_35_13_AM.edm: #REF!
Name _bdm.FastTrackBookmark.11_1_2023_1_59_16_PM.edm: Sand!$X$143
Name A_ALL_AESI: #REF!
Name A_ALL_AESI: AESI_Annotation_Sheet!$A$1:$AT$315
Name A_ALL_KEYWORDS_TYPE_ScalarContributed_EQTY_200022132: AESI_Annotation_Sheet!$248:$248,AESI_Annotation_Sheet!$251:$261,AESI_Annotation_Sheet!$302:$302,AESI_Annotation_Sheet!$306:$308,AESI_Annotation_Sheet!$313:$315
Name A_ALL_KEYWORDS_TYPE_ScalarContributed_EQTY_200022132: AESI_Annotation_Sheet!$248:$248,AESI_Annotation_Sheet!$302:$302,AESI_Annotation_Sheet!$306:$308,AESI_Annotation_Sheet!$313:$315,AESI_Annotation_Sheet!$251:$261
Name A_ALL_KEYWORDS_TYPE_ScalarContributed_ISSR_208021701: AESI_Annotation_Sheet!$9:$9,AESI_Annotation_Sheet!$39:$39
Name A_ALL_KEYWORDS_TYPE_ScalarReference_EQTY_200022132: AESI_Annotation_Sheet!$241:$246
Name A_ALL_KEYWORDS_TYPE_ScalarReference_ISSR_208021701: AESI_Annotation_Sheet!$6:$7
Name A_ALL_PERIODS_AESI: AESI_Annotation_Sheet!$F$1:$AT$1
Name A_ALL_SECTION_KEYWORDS_EQTY_200000592_13K: #REF!
Name A_ALL_SECTION_KEYWORDS_EQTY_200000592_13K: #REF!
Name A_ALL_SECTION_KEYWORDS_EQTY_200022132_1314: AESI_Annotation_Sheet!$C$304
Name A_ALL_SECTION_KEYWORDS_EQTY_200022132_1319: AESI_Annotation_Sheet!$C$306:$C$309
Name A_ALL_SECTION_KEYWORDS_EQTY_200022132_131E: AESI_Annotation_Sheet!$C$311
Name A_ALL_SECTION_KEYWORDS_EQTY_200022132_131O: AESI_Annotation_Sheet!$C$313:$C$315
Name A_ALL_SECTION_KEYWORDS_EQTY_200022132_13A: AESI_Annotation_Sheet!$C$248:$C$261
Name A_ALL_SECTION_KEYWORDS_EQTY_200022132_13A: AESI_Annotation_Sheet!$C$248:$C$261
Name A_ALL_SECTION_KEYWORDS_EQTY_200022132_13K: AESI_Annotation_Sheet!$C$263:$C$277
Name A_ALL_SECTION_KEYWORDS_EQTY_200022132_13U: AESI_Annotation_Sheet!$C$279:$C$294
Name A_ALL_SECTION_KEYWORDS_EQTY_200022132_13V: AESI_Annotation_Sheet!$C$296
Name A_ALL_SECTION_KEYWORDS_EQTY_200022132_13W: AESI_Annotation_Sheet!$C$298:$C$302
Name A_ALL_SECTION_KEYWORDS_EQTY_200022132_Reference_Data: AESI_Annotation_Sheet!$C$241:$C$246
Name A_ALL_SECTION_KEYWORDS_ISSR_208000084_136J: #REF!,#REF!
Name A_ALL_SECTION_KEYWORDS_ISSR_208000084_136J: #REF!,#REF!
Name A_ALL_SECTION_KEYWORDS_ISSR_208021701_1314: AESI_Annotation_Sheet!$C$41:$C$70
Name A_ALL_SECTION_KEYWORDS_ISSR_208021701_13168: AESI_Annotation_Sheet!$C$132:$C$193
Name A_ALL_SECTION_KEYWORDS_ISSR_208021701_1316S: AESI_Annotation_Sheet!$C$195:$C$200
Name A_ALL_SECTION_KEYWORDS_ISSR_208021701_1316T: AESI_Annotation_Sheet!$C$202:$C$211
Name A_ALL_SECTION_KEYWORDS_ISSR_208021701_1316U: AESI_Annotation_Sheet!$C$213:$C$227
Name A_ALL_SECTION_KEYWORDS_ISSR_208021701_1319: AESI_Annotation_Sheet!$C$72:$C$90
Name A_ALL_SECTION_KEYWORDS_ISSR_208021701_131E: AESI_Annotation_Sheet!$C$92:$C$108
Name A_ALL_SECTION_KEYWORDS_ISSR_208021701_131J: AESI_Annotation_Sheet!$C$110:$C$122
Name A_ALL_SECTION_KEYWORDS_ISSR_208021701_131O: AESI_Annotation_Sheet!$C$124
Name A_ALL_SECTION_KEYWORDS_ISSR_208021701_131O: AESI_Annotation_Sheet!$C$124,AESI_Annotation_Sheet!$C$126
Name A_ALL_SECTION_KEYWORDS_ISSR_208021701_131P: AESI_Annotation_Sheet!$C$128:$C$130
Name A_ALL_SECTION_KEYWORDS_ISSR_208021701_136E: AESI_Annotation_Sheet!$C$229:$C$238
Name A_ALL_SECTION_KEYWORDS_ISSR_208021701_13A: AESI_Annotation_Sheet!$C$9
Name A_ALL_SECTION_KEYWORDS_ISSR_208021701_13U: AESI_Annotation_Sheet!$C$11:$C$30
Name A_ALL_SECTION_KEYWORDS_ISSR_208021701_13V: AESI_Annotation_Sheet!$C$32:$C$39
Name A_ALL_SECTION_KEYWORDS_ISSR_208021701_Reference_Data: AESI_Annotation_Sheet!$C$6:$C$7
Name A_ALL_SLB: #REF!
Name A_ALL_SLB: #REF!
Name A_CURRENCY_EQTY_200022132_PRI: AESI_Annotation_Sheet!$E$245
Name A_CURRENCY_EQTY_200022132_PUB: AESI_Annotation_Sheet!$E$244
Name A_CURRENCY_EQTY_200022132_REP: AESI_Annotation_Sheet!$E$246
Name A_CURRENCY_ISSR_208021701_REP: AESI_Annotation_Sheet!$E$7
Name A_ENTITY_DATA_EQTY_200022132: AESI_Annotation_Sheet!$E$240:$AT$315
Name A_ENTITY_DATA_ISSR_208021701: AESI_Annotation_Sheet!$E$5:$AT$238
Name A_KEYWORD_EQTY_200022132_AMER_CONVICTION: AESI_Annotation_Sheet!$250:$250
Name A_KEYWORD_EQTY_200022132_AMER_LIST: AESI_Annotation_Sheet!$248:$248
Name A_KEYWORD_EQTY_200022132_BETA_ANALYST: AESI_Annotation_Sheet!$313:$313
Name A_KEYWORD_EQTY_200022132_BVPS: AESI_Annotation_Sheet!$304:$304
Name A_KEYWORD_EQTY_200022132_BVPS_PUB: AESI_Annotation_Sheet!$263:$263
Name A_KEYWORD_EQTY_200022132_CEEE_NDEBT: AESI_Annotation_Sheet!$272:$272
Name A_KEYWORD_EQTY_200022132_CF_NI_PRE_PREF: AESI_Annotation_Sheet!$311:$311
Name A_KEYWORD_EQTY_200022132_COMMON_DIV_PAID: AESI_Annotation_Sheet!$290:$290

Sheet __FDSCACHE__
B1: This sheet contains FactSet XML data for use with this workbook's =FDS codes. Modifying the worksheet's contents may damage the workbook's =FDS functionality.

Sheet Summary
A2: x | B2: Atlas Energy Solutions
B3: Summary Sheet
B4: (US$ Millions)
C6: 2020 | D6: 2021 | E6: 2022 | F6: 2023 | G6: 2024 | H6: 2025 | I6: 2026 | J6: 2027 | K6: 2028
B8: Revenue
B9: Sand Revenue | C9: {=INDEX('Income Statement'!$DE$9:$EB$9,MATCH(Summary!C$6,'Income Statement'!$DE$5:$EB$5,0))} -> 79.869601 | D9: {=INDEX('Income Statement'!$DE$9:$EB$9,MATCH(Summary!D$6,'Income Statement'!$DE$5:$EB$5,0))} -> 142.5198 | E9: {=INDEX('Income Statement'!$DE$9:$EB$9,MATCH(Summary!E$6,'Income Statement'!$DE$5:$EB$5,0))} -> 408.32798 | F9: {=INDEX('Income Statement'!$DE$9:$EB$9,MATCH(Summary!F$6,'Income Statement'!$DE$5:$EB$5,0))} -> 468.119 | G9: {=INDEX('Income Statement'!$DE$9:$EB$9,MATCH(Summary!G$6,'Income Statement'!$DE$5:$EB$5,0))} -> 515.434 | H9: {=INDEX('Income Statement'!$DE$9:$EB$9,MATCH(Summary!H$6,'Income Statement'!$DE$5:$EB$5,0))} -> 629.80808 | I9: {=INDEX('Income Statement'!$DE$9:$EB$9,MATCH(Summary!I$6,'Income Statement'!$DE$5:$EB$5,0))} -> 687.46864 | J9: {=INDEX('Income Statement'!$DE$9:$EC$9,MATCH(Summary!J$6,'Income Statement'!$DE$5:$EC$5,0))} -> 727.51171 | K9: {=INDEX('Income Statement'!$DE$9:$EC$9,MATCH(Summary!K$6,'Income Statement'!$DE$5:$EC$5,0))} -> 748.24488
B10: Logistics Revenue | C10: {=INDEX('Income Statement'!$DE$10:$EC$10,MATCH(Summary!C$6,'Income Statement'!$DE$5:$EC$5,0))} -> 31.902027 | D10: {=INDEX('Income Statement'!$DE$10:$EC$10,MATCH(Summary!D$6,'Income Statement'!$DE$5:$EC$5,0))} -> 29.885861 | E10: {=INDEX('Income Statement'!$DE$10:$EC$10,MATCH(Summary!E$6,'Income Statement'!$DE$5:$EC$5,0))} -> 74.265797 | F10: {=INDEX('Income Statement'!$DE$10:$EC$10,MATCH(Summary!F$6,'Income Statement'!$DE$5:$EC$5,0))} -> 145.841 | G10: {=INDEX('Income Statement'!$DE$10:$EC$10,MATCH(Summary!G$6,'Income Statement'!$DE$5:$EC$5,0))} -> 542.0102 | H10: {=INDEX('Income Statement'!$DE$10:$EC$10,MATCH(Summary!H$6,'Income Statement'!$DE$5:$EC$5,0))} -> 663.71998 | I10: {=INDEX('Income Statement'!$DE$10:$EC$10,MATCH(Summary!I$6,'Income Statement'!$DE$5:$EC$5,0))} -> 670.09294 | J10: {=INDEX('Income Statement'!$DE$10:$EC$10,MATCH(Summary!J$6,'Income Statement'!$DE$5:$EC$5,0))} -> 681.56055 | K10: {=INDEX('Income Statement'!$DE$10:$EC$10,MATCH(Summary!K$6,'Income Statement'!$DE$5:$EC$5,0))} -> 682.754
B11: Total Revenue | C11: =INDEX('Income Statement'!$DE11:$EB11,MATCH(Summary!C$6,'Income Statement'!$DE$5:$EB$5,0)) -> 111.77163 | D11: {=INDEX('Income Statement'!$DE11:$EB11,MATCH(Summary!D$6,'Income Statement'!$DE$5:$EB$5,0))} -> 172.40566 | E11: {=INDEX('Income Statement'!$DE11:$EB11,MATCH(Summary!E$6,'Income Statement'!$DE$5:$EB$5,0))} -> 482.59377 | F11: {=INDEX('Income Statement'!$DE11:$EB11,MATCH(Summary!F$6,'Income Statement'!$DE$5:$EB$5,0))} -> 613.96 | G11: {=INDEX('Income Statement'!$DE11:$EB11,MATCH(Summary!G$6,'Income Statement'!$DE$5:$EB$5,0))} -> 1057.4442 | H11: {=INDEX('Income Statement'!$DE11:$EB11,MATCH(Summary!H$6,'Income Statement'!$DE$5:$EB$5,0))} -> 1293.5281 | I11: {=INDEX('Income Statement'!$DE11:$EB11,MATCH(Summary!I$6,'Income Statement'!$DE$5:$EB$5,0))} -> 1357.5616 | J11: {=INDEX('Income Statement'!$DE11:$EC11,MATCH(Summary!J$6,'Income Statement'!$DE$5:$EC$5,0))} -> 1409.0723 | K11: {=INDEX('Income Statement'!$DE11:$EC11,MATCH(Summary!K$6,'Income Statement'!$DE$5:$EC$5,0))} -> 1430.9989
B13: Operating Income
B14: Sand | C14: {=INDEX(Sand!$BF$22:$BP$22,MATCH(Summary!C$6,Sand!$BF$5:$BP$5,0))} -> 18.263283 | D14: {=INDEX(Sand!$BF$22:$BP$22,MATCH(Summary!D$6,Sand!$BF$5:$BP$5,0))} -> 71.900625 | E14: {=INDEX(Sand!$BF$22:$BP$22,MATCH(Summary!E$6,Sand!$BF$5:$BP$5,0))} -> 254.44963 | F14: {=INDEX(Sand!$BF$22:$BP$22,MATCH(Summary!F$6,Sand!$BF$5:$BP$5,0))} -> 295.2622 | G14: {=INDEX(Sand!$BF$22:$BP$22,MATCH(Summary!G$6,Sand!$BF$5:$BP$5,0))} -> 144.59576 | H14: {=INDEX(Sand!$BF$22:$BP$22,MATCH(Summary!H$6,Sand!$BF$5:$BP$5,0))} -> 238.41644 | I14: {=INDEX(Sand!$BF$22:$BP$22,MATCH(Summary!I$6,Sand!$BF$5:$BP$5,0))} -> 304.80678 | J14: {=INDEX(Sand!$BF$22:$BP$22,MATCH(Summary!J$6,Sand!$BF$5:$BP$5,0))} -> 344.60675 | K14: {=INDEX(Sand!$BF$22:$BP$22,MATCH(Summary!K$6,Sand!$BF$5:$BP$5,0))} -> 363.2038
B15: Logistics | C15: {=INDEX(Logistics!$BF$18:$BP$18,MATCH(Summary!C$6,Logistics!$BF$5:$BP$5,0))} -> 0.08921977 | D15: {=INDEX(Logistics!$BF$18:$BP$18,MATCH(Summary!D$6,Logistics!$BF$5:$BP$5,0))} -> 3.0858606 | E15: {=INDEX(Logistics!$BF$18:$BP$18,MATCH(Summary!E$6,Logistics!$BF$5:$BP$5,0))} -> 6.6616839 | F15: {=INDEX(Logistics!$BF$18:$BP$18,MATCH(Summary!F$6,Logistics!$BF$5:$BP$5,0))} -> 23.101957 | G15: {=INDEX(Logistics!$BF$18:$BP$18,MATCH(Summary!G$6,Logistics!$BF$5:$BP$5,0))} -> 83.290509 | H15: {=INDEX(Logistics!$BF$18:$BP$18,MATCH(Summary!H$6,Logistics!$BF$5:$BP$5,0))} -> 95.947124 | I15: {=INDEX(Logistics!$BF$18:$BP$18,MATCH(Summary!I$6,Logistics!$BF$5:$BP$5,0))} -> 95.684856 | J15: {=INDEX(Logistics!$BF$18:$BP$18,MATCH(Summary!J$6,Logistics!$BF$5:$BP$5,0))} -> 97.108254 | K15: {=INDEX(Logistics!$BF$18:$BP$18,MATCH(Summary!K$6,Logistics!$BF$5:$BP$5,0))} -> 97.246176
B16: Total Operating Income | C16: {=INDEX('Income Statement'!$DU31:$EC31,MATCH(Summary!C$6,'Income Statement'!$DU$5:$EC$5,0))} -> 1.3806168 | D16: {=INDEX('Income Statement'!$DU31:$EC31,MATCH(Summary!D$6,'Income Statement'!$DU$5:$EC$5,0))} -> 47.189592 | E16: {=INDEX('Income Statement'!$DU31:$EC31,MATCH(Summary!E$6,'Income Statement'!$DU$5:$EC$5,0))} -> 232.65733 | F16: {=INDEX('Income Statement'!$DU31:$EC31,MATCH(Summary!F$6,'Income Statement'!$DU$5:$EC$5,0))} -> 265.13 | G16: {=INDEX('Income Statement'!$DU31:$EC31,MATCH(Summary!G$6,'Income Statement'!$DU$5:$EC$5,0))} -> 116.10293 | H16: {=INDEX('Income Statement'!$DU31:$EC31,MATCH(Summary!H$6,'Income Statement'!$DU$5:$EC$5,0))} -> 229.56618 | I16: {=INDEX('Income Statement'!$DU31:$EC31,MATCH(Summary!I$6,'Income Statement'!$DU$5:$EC$5,0))} -> 295.69426 | J16: {=INDEX('Income Statement'!$DU31:$EC31,MATCH(Summary!J$6,'Income Statement'!$DU$5:$EC$5,0))} -> 336.91763 | K16: {=INDEX('Income Statement'!$DU31:$EC31,MATCH(Summary!K$6,'Income Statement'!$DU$5:$EC$5,0))} -> 355.65259
B18: Interest Expense | C18: {=INDEX('Income Statement'!$DU32:$EC32,MATCH(Summary!C$6,'Income Statement'!$DU$5:$EC$5,0))} -> -32.819165 | D18: {=INDEX('Income Statement'!$DU32:$EC32,MATCH(Summary!D$6,'Income Statement'!$DU$5:$EC$5,0))} -> -30.276282 | E18: {=INDEX('Income Statement'!$DU32:$EC32,MATCH(Summary!E$6,'Income Statement'!$DU$5:$EC$5,0))} -> -15.739831 | F18: {=INDEX('Income Statement'!$DU32:$EC32,MATCH(Summary!F$6,'Income Statement'!$DU$5:$EC$5,0))} -> -7.689 | G18: {=INDEX('Income Statement'!$DU32:$EC32,MATCH(Summary!G$6,'Income Statement'!$DU$5:$EC$5,0))} -> -37.822 | H18: {=INDEX('Income Statement'!$DU32:$EC32,MATCH(Summary!H$6,'Income Statement'!$DU$5:$EC$5,0))} -> -24.391786 | I18: {=INDEX('Income Statement'!$DU32:$EC32,MATCH(Summary!I$6,'Income Statement'!$DU$5:$EC$5,0))} -> -13.037606 | J18: {=INDEX('Income Statement'!$DU32:$EC32,MATCH(Summary!J$6,'Income Statement'!$DU$5:$EC$5,0))} -> -13.037606 | K18: {=INDEX('Income Statement'!$DU32:$EC32,MATCH(Summary!K$6,'Income Statement'!$DU$5:$EC$5,0))} -> -13.037606
B19: Other Income | C19: {=INDEX('Income Statement'!$DU33:$EC33,MATCH(Summary!C$6,'Income Statement'!$DU$5:$EC$5,0))} -> -3.8814379 | D19: {=INDEX('Income Statement'!$DU33:$EC33,MATCH(Summary!D$6,'Income Statement'!$DU$5:$EC$5,0))} -> 4.5908677 | E19: {=INDEX('Income Statement'!$DU33:$EC33,MATCH(Summary!E$6,'Income Statement'!$DU$5:$EC$5,0))} -> 0 | F19: {=INDEX('Income Statement'!$DU33:$EC33,MATCH(Summary!F$6,'Income Statement'!$DU$5:$EC$5,0))} -> 0.43 | G19: {=INDEX('Income Statement'!$DU33:$EC33,MATCH(Summary!G$6,'Income Statement'!$DU$5:$EC$5,0))} -> 0.45 | H19: {=INDEX('Income Statement'!$DU33:$EC33,MATCH(Summary!H$6,'Income Statement'!$DU$5:$EC$5,0))} -> 0 | I19: {=INDEX('Income Statement'!$DU33:$EC33,MATCH(Summary!I$6,'Income Statement'!$DU$5:$EC$5,0))} -> 0 | J19: {=INDEX('Income Statement'!$DU33:$EC33,MATCH(Summary!J$6,'Income Statement'!$DU$5:$EC$5,0))} -> 0 | K19: {=INDEX('Income Statement'!$DU33:$EC33,MATCH(Summary!K$6,'Income Statement'!$DU$5:$EC$5,0))} -> 0
B20: Pre-tax Income | C20: {=INDEX('Income Statement'!$DU34:$EC34,MATCH(Summary!C$6,'Income Statement'!$DU$5:$EC$5,0))} -> -35.319986 | D20: {=INDEX('Income Statement'!$DU34:$EC34,MATCH(Summary!D$6,'Income Statement'!$DU$5:$EC$5,0))} -> 21.504178 | E20: {=INDEX('Income Statement'!$DU34:$EC34,MATCH(Summary!E$6,'Income Statement'!$DU$5:$EC$5,0))} -> 216.9175 | F20: {=INDEX('Income Statement'!$DU34:$EC34,MATCH(Summary!F$6,'Income Statement'!$DU$5:$EC$5,0))} -> 257.871 | G20: {=INDEX('Income Statement'!$DU34:$EC34,MATCH(Summary!G$6,'Income Statement'!$DU$5:$EC$5,0))} -> 78.730925 | H20: {=INDEX('Income Statement'!$DU34:$EC34,MATCH(Summary!H$6,'Income Statement'!$DU$5:$EC$5,0))} -> 205.17439 | I20: {=INDEX('Income Statement'!$DU34:$EC34,MATCH(Summary!I$6,'Income Statement'!$DU$5:$EC$5,0))} -> 282.65665 | J20: {=INDEX('Income Statement'!$DU34:$EC34,MATCH(Summary!J$6,'Income Statement'!$DU$5:$EC$5,0))} -> 323.88002 | K20: {=INDEX('Income Statement'!$DU34:$EC34,MATCH(Summary!K$6,'Income Statement'!$DU$5:$EC$5,0))} -> 342.61499
B21: Taxes | C21: {=INDEX('Income Statement'!$DU36:$EC36,MATCH(Summary!C$6,'Income Statement'!$DU$5:$EC$5,0))} -> -0.3729235 | D21: {=INDEX('Income Statement'!$DU36:$EC36,MATCH(Summary!D$6,'Income Statement'!$DU$5:$EC$5,0))} -> -0.47040432 | E21: {=INDEX('Income Statement'!$DU36:$EC36,MATCH(Summary!E$6,'Income Statement'!$DU$5:$EC$5,0))} -> -2.0292631 | F21: {=INDEX('Income Statement'!$DU36:$EC36,MATCH(Summary!F$6,'Income Statement'!$DU$5:$EC$5,0))} -> -31.378 | G21: {=INDEX('Income Statement'!$DU36:$EC36,MATCH(Summary!G$6,'Income Statement'!$DU$5:$EC$5,0))} -> -15.770585 | H21: {=INDEX('Income Statement'!$DU36:$EC36,MATCH(Summary!H$6,'Income Statement'!$DU$5:$EC$5,0))} -> -43.086623 | I21: {=INDEX('Income Statement'!$DU36:$EC36,MATCH(Summary!I$6,'Income Statement'!$DU$5:$EC$5,0))} -> -59.357896 | J21: {=INDEX('Income Statement'!$DU36:$EC36,MATCH(Summary!J$6,'Income Statement'!$DU$5:$EC$5,0))} -> -68.014804 | K21: {=INDEX('Income Statement'!$DU36:$EC36,MATCH(Summary!K$6,'Income Statement'!$DU$5:$EC$5,0))} -> -71.949147
B22: Minority Interest | C22: {=INDEX('Income Statement'!$DU38:$EC38,MATCH(Summary!C$6,'Income Statement'!$DU$5:$EC$5,0))} -> 0 | D22: {=INDEX('Income Statement'!$DU38:$EC38,MATCH(Summary!D$6,'Income Statement'!$DU$5:$EC$5,0))} -> 0 | E22: {=INDEX('Income Statement'!$DU38:$EC38,MATCH(Summary!E$6,'Income Statement'!$DU$5:$EC$5,0))} -> 0 | F22: {=INDEX('Income Statement'!$DU38:$EC38,MATCH(Summary!F$6,'Income Statement'!$DU$5:$EC$5,0))} -> 0 | G22: {=INDEX('Income Statement'!$DU38:$EC38,MATCH(Summary!G$6,'Income Statement'!$DU$5:$EC$5,0))} -> 0 | H22: {=INDEX('Income Statement'!$DU38:$EC38,MATCH(Summary!H$6,'Income Statement'!$DU$5:$EC$5,0))} -> 0 | I22: {=INDEX('Income Statement'!$DU38:$EC38,MATCH(Summary!I$6,'Income Statement'!$DU$5:$EC$5,0))} -> 0 | J22: {=INDEX('Income Statement'!$DU38:$EC38,MATCH(Summary!J$6,'Income Statement'!$DU$5:$EC$5,0))} -> 0 | K22: {=INDEX('Income Statement'!$DU38:$EC38,MATCH(Summary!K$6,'Income Statement'!$DU$5:$EC$5,0))} -> 0
B23: Net Income | C23: {=INDEX('Income Statement'!$DU39:$EC39,MATCH(Summary!C$6,'Income Statement'!$DU$5:$EC$5,0))} -> -35.692909 | D23: {=INDEX('Income Statement'!$DU39:$EC39,MATCH(Summary!D$6,'Income Statement'!$DU$5:$EC$5,0))} -> 21.033774 | E23: {=INDEX('Income Statement'!$DU39:$EC39,MATCH(Summary!E$6,'Income Statement'!$DU$5:$EC$5,0))} -> 214.88823 | F23: {=INDEX('Income Statement'!$DU39:$EC39,MATCH(Summary!F$6,'Income Statement'!$DU$5:$EC$5,0))} -> 226.493 | G23: {=INDEX('Income Statement'!$DU39:$EC39,MATCH(Summary!G$6,'Income Statement'!$DU$5:$EC$5,0))} -> 62.96034 | H23: {=INDEX('Income Statement'!$DU39:$EC39,MATCH(Summary!H$6,'Income Statement'!$DU$5:$EC$5,0))} -> 162.08777 | I23: {=INDEX('Income Statement'!$DU39:$EC39,MATCH(Summary!I$6,'Income Statement'!$DU$5:$EC$5,0))} -> 223.29875 | J23: {=INDEX('Income Statement'!$DU39:$EC39,MATCH(Summary!J$6,'Income Statement'!$DU$5:$EC$5,0))} -> 255.86522 | K23: {=INDEX('Income Statement'!$DU39:$EC39,MATCH(Summary!K$6,'Income Statement'!$DU$5:$EC$5,0))} -> 270.66584
B25: Diluted Shares Outstanding | C25: {=INDEX('Income Statement'!$DE59:$EB59,MATCH(Summary!C$6,'Income Statement'!$DE$5:$EB$5,0))} -> 0 | D25: {=INDEX('Income Statement'!$DE59:$EB59,MATCH(Summary!D$6,'Income Statement'!$DE$5:$EB$5,0))} -> 0 | E25: {=INDEX('Income Statement'!$DE59:$EB59,MATCH(Summary!E$6,'Income Statement'!$DE$5:$EB$5,0))} -> 0 | F25: {=INDEX('Income Statement'!$DE59:$EB59,MATCH(Summary!F$6,'Income Statement'!$DE$5:$EB$5,0))} -> 100.242 | G25: {=INDEX('Income Statement'!$DE59:$EB59,MATCH(Summary!G$6,'Income Statement'!$DE$5:$EB$5,0))} -> 111.078 | H25: {=INDEX('Income Statement'!$DE59:$EB59,MATCH(Summary!H$6,'Income Statement'!$DE$5:$EB$5,0))} -> 111.078 | I25: {=INDEX('Income Statement'!$DE59:$EB59,MATCH(Summary!I$6,'Income Statement'!$DE$5:$EB$5,0))} -> 111.078 | J25: {=INDEX('Income Statement'!$DE59:$EC59,MATCH(Summary!J$6,'Income Statement'!$DE$5:$EC$5,0))} -> 111.078 | K25: {=INDEX('Income Statement'!$DE59:$EC59,MATCH(Summary!K$6,'Income Statement'!$DE$5:$EC$5,0))} -> 111.078
B26: Adjusted EPS | C26: {=INDEX('Income Statement'!$DE43:$EB43,MATCH(Summary!C$6,'Income Statement'!$DE$5:$EB$5,0))} -> #DIV/0! | D26: {=INDEX('Income Statement'!$DE43:$EB43,MATCH(Summary!D$6,'Income Statement'!$DE$5:$EB$5,0))} -> #DIV/0! | E26: {=INDEX('Income Statement'!$DE43:$EB43,MATCH(Summary!E$6,'Income Statement'!$DE$5:$EB$5,0))} -> #DIV/0! | F26: {=INDEX('Income Statement'!$DE43:$EB43,MATCH(Summary!F$6,'Income Statement'!$DE$5:$EB$5,0))} -> 2.2594621 | G26: {=INDEX('Income Statement'!$DE43:$EB43,MATCH(Summary!G$6,'Income Statement'!$DE$5:$EB$5,0))} -> 0.56681197 | H26: {=INDEX('Income Statement'!$DE43:$EB43,MATCH(Summary!H$6,'Income Statement'!$DE$5:$EB$5,0))} -> 1.4592248 | I26: {=INDEX('Income Statement'!$DE43:$EB43,MATCH(Summary!I$6,'Income Statement'!$DE$5:$EB$5,0))} -> 2.0102878 | J26: {=INDEX('Income Statement'!$DE43:$EC43,MATCH(Summary!J$6,'Income Statement'!$DE$5:$EC$5,0))} -> 2.3034734 | K26: {=INDEX('Income Statement'!$DE43:$EC43,MATCH(Summary!K$6,'Income Statement'!$DE$5:$EC$5,0))} -> 2.4367187
B28: Adjusted EBITDA
B29: Sand | C29: {=INDEX('Income Statement'!$DU81:$EC81,MATCH(Summary!C$6,'Income Statement'!$DU$5:$EC$5,0))} -> 0 | D29: {=INDEX('Income Statement'!$DU81:$EC81,MATCH(Summary!D$6,'Income Statement'!$DU$5:$EC$5,0))} -> 0 | E29: {=INDEX('Income Statement'!$DU81:$EC81,MATCH(Summary!E$6,'Income Statement'!$DU$5:$EC$5,0))} -> 0 | F29: {=INDEX('Income Statement'!$DU81:$EC81,MATCH(Summary!F$6,'Income Statement'!$DU$5:$EC$5,0))} -> 0 | G29: {=INDEX('Income Statement'!$DU81:$EC81,MATCH(Summary!G$6,'Income Statement'!$DU$5:$EC$5,0))} -> 0 | H29: {=INDEX('Income Statement'!$DU81:$EC81,MATCH(Summary!H$6,'Income Statement'!$DU$5:$EC$5,0))} -> 0 | I29: {=INDEX('Income Statement'!$DU81:$EC81,MATCH(Summary!I$6,'Income Statement'!$DU$5:$EC$5,0))} -> 0 | J29: {=INDEX('Income Statement'!$DU81:$EC81,MATCH(Summary!J$6,'Income Statement'!$DU$5:$EC$5,0))} -> 0 | K29: {=INDEX('Income Statement'!$DU81:$EC81,MATCH(Summary!K$6,'Income Statement'!$DU$5:$EC$5,0))} -> 0
B30: Logistics | C30: {=INDEX('Income Statement'!$DU82:$EC82,MATCH(Summary!C$6,'Income Statement'!$DU$5:$EC$5,0))} -> 0 | D30: {=INDEX('Income Statement'!$DU82:$EC82,MATCH(Summary!D$6,'Income Statement'!$DU$5:$EC$5,0))} -> 0 | E30: {=INDEX('Income Statement'!$DU82:$EC82,MATCH(Summary!E$6,'Income Statement'!$DU$5:$EC$5,0))} -> 0 | F30: {=INDEX('Income Statement'!$DU82:$EC82,MATCH(Summary!F$6,'Income Statement'!$DU$5:$EC$5,0))} -> 0 | G30: {=INDEX('Income Statement'!$DU82:$EC82,MATCH(Summary!G$6,'Income Statement'!$DU$5:$EC$5,0))} -> 0 | H30: {=INDEX('Income Statement'!$DU82:$EC82,MATCH(Summary!H$6,'Income Statement'!$DU$5:$EC$5,0))} -> 0 | I30: {=INDEX('Income Statement'!$DU82:$EC82,MATCH(Summary!I$6,'Income Statement'!$DU$5:$EC$5,0))} -> 0 | J30: {=INDEX('Income Statement'!$DU82:$EC82,MATCH(Summary!J$6,'Income Statement'!$DU$5:$EC$5,0))} -> 0 | K30: {=INDEX('Income Statement'!$DU82:$EC82,MATCH(Summary!K$6,'Income Statement'!$DU$5:$EC$5,0))} -> 0
B31: Total Adjusted EBITDA | C31: {=INDEX('Income Statement'!$DE45:$EB45,MATCH(Summary!C$6,'Income Statement'!$DE$5:$EB$5,0))} -> 22.897311 | D31: {=INDEX('Income Statement'!$DE45:$EB45,MATCH(Summary!D$6,'Income Statement'!$DE$5:$EB$5,0))} -> 71.730486 | E31: {=INDEX('Income Statement'!$DE45:$EB45,MATCH(Summary!E$6,'Income Statement'!$DE$5:$EB$5,0))} -> 261.11132 | F31: {=INDEX('Income Statement'!$DE45:$EB45,MATCH(Summary!F$6,'Income Statement'!$DE$5:$EB$5,0))} -> 304.928 | G31: {=INDEX('Income Statement'!$DE45:$EB45,MATCH(Summary!G$6,'Income Statement'!$DE$5:$EB$5,0))} -> 227.75727 | H31: {=INDEX('Income Statement'!$DE45:$EB45,MATCH(Summary!H$6,'Income Statement'!$DE$5:$EB$5,0))} -> 334.36356 | I31: {=INDEX('Income Statement'!$DE45:$EB45,MATCH(Summary!I$6,'Income Statement'!$DE$5:$EB$5,0))} -> 400.49164 | J31: {=INDEX('Income Statement'!$DE45:$EB45,MATCH(Summary!J$6,'Income Statement'!$DE$5:$EB$5,0))} -> 441.71501 | K31: {=INDEX('Income Statement'!$DE45:$EC45,MATCH(Summary!K$6,'Income Statement'!$DE$5:$EC$5,0))} -> 460.44997
B32: Check
B34: Adjusted EBITDA Margin
B35: Sand | C35: =C29/C9 -> 0 | D35: =D29/D9 -> 0 | E35: =E29/E9 -> 0 | F35: =F29/F9 -> 0 | G35: =G29/G9 -> 0 | H35: =H29/H9 -> 0 | I35: =I29/I9 -> 0 | J35: =J29/J9 -> 0 | K35: =K29/K9 -> 0
B36: Logistics | C36: =C30/C10 -> 0 | D36: =D30/D10 -> 0 | E36: =E30/E10 -> 0 | F36: =F30/F10 -> 0 | G36: =G30/G10 -> 0 | H36: =H30/H10 -> 0 | I36: =I30/I10 -> 0 | J36: =J30/J10 -> 0 | K36: =K30/K10 -> 0
B37: Total Adjusted EBITDA Margin | C37: =C31/C11 -> 0.20485799 | D37: =D31/D11 -> 0.41605644 | E37: =E31/E11 -> 0.5410582 | F37: =F31/F11 -> 0.49665776 | G37: =G31/G11 -> 0.21538467 | H37: =H31/H11 -> 0.25848961 | I37: =I31/I11 -> 0.29500808 | J37: =J31/J11 -> 0.31347931 | K37: =K31/K11 -> 0.32176823
B39: Free Cash Flow | C39: {=INDEX('Cash Flow'!$DE58:$EB58,MATCH(Summary!C$6,'Cash Flow'!$DE$5:$EB$5,0))} -> 2.954 | D39: {=INDEX('Cash Flow'!$DE58:$EB58,MATCH(Summary!D$6,'Cash Flow'!$DE$5:$EB$5,0))} -> 24.074616 | E39: {=INDEX('Cash Flow'!$DE58:$EB58,MATCH(Summary!E$6,'Cash Flow'!$DE$5:$EB$5,0))} -> 116.24989 | F39: {=INDEX('Cash Flow'!$DE58:$EB58,MATCH(Summary!F$6,'Cash Flow'!$DE$5:$EB$5,0))} -> -66.455 | G39: {=INDEX('Cash Flow'!$DE58:$EB58,MATCH(Summary!G$6,'Cash Flow'!$DE$5:$EB$5,0))} -> -103.57034 | H39: {=INDEX('Cash Flow'!$DE58:$EB58,MATCH(Summary!H$6,'Cash Flow'!$DE$5:$EB$5,0))} -> 248.46755 | I39: {=INDEX('Cash Flow'!$DE58:$EB58,MATCH(Summary!I$6,'Cash Flow'!$DE$5:$EB$5,0))} -> 317.11052 | J39: {=INDEX('Cash Flow'!$DE58:$EB58,MATCH(Summary!J$6,'Cash Flow'!$DE$5:$EB$5,0))} -> 351.14786 | K39: {=INDEX('Cash Flow'!$DE58:$EC58,MATCH(Summary!K$6,'Cash Flow'!$DE$5:$EC$5,0))} -> -154.56676
B40: FCF/EBITDA conversion | C40: =C39/C31 -> 0.12901078 | D40: =D39/D31 -> 0.33562599 | E40: =E39/E31 -> 0.44521201 | F40: =F39/F31 -> -0.21793669 | G40: =G39/G31 -> -0.45474 | H40: =H39/H31 -> 0.74310595 | I40: =I39/I31 -> 0.79180311 | J40: =J39/J31 -> 0.79496474 | K40: =K39/K31 -> -0.33568632
B41: FCF/Revenue Conversion | C41: =C39/C11 -> 0.026428889 | D41: =D39/D11 -> 0.13963936 | E41: =E39/E11 -> 0.24088561 | F41: =F39/F11 -> -0.10823995 | G41: =G39/G11 -> -0.097944024 | H41: =H39/H11 -> 0.19208517 | I41: =I39/I11 -> 0.23358832 | J41: =J39/J11 -> 0.249205 | K41: =K39/K11 -> -0.10801319
B43: Net Debt | C43: {=INDEX('Balance Sheet'!$DE$57:$EB$57,MATCH(Summary!C$6,'Balance Sheet'!$DE$5:$EB$5,0))} -> 137.03977 | D43: {=INDEX('Balance Sheet'!$DE$57:$EB$57,MATCH(Summary!D$6,'Balance Sheet'!$DE$5:$EB$5,0))} -> 137.13801 | E43: {=INDEX('Balance Sheet'!$DE$57:$EB$57,MATCH(Summary!E$6,'Balance Sheet'!$DE$5:$EB$5,0))} -> 65.163794 | F43: {=INDEX('Balance Sheet'!$DE$57:$EB$57,MATCH(Summary!F$6,'Balance Sheet'!$DE$5:$EB$5,0))} -> -37.354 | G43: {=INDEX('Balance Sheet'!$DE$57:$EB$57,MATCH(Summary!G$6,'Balance Sheet'!$DE$5:$EB$5,0))} -> 414.90906 | H43: {=INDEX('Balance Sheet'!$DE$57:$EB$57,MATCH(Summary!H$6,'Balance Sheet'!$DE$5:$EB$5,0))} -> 278.40813 | I43: {=INDEX('Balance Sheet'!$DE$57:$EB$57,MATCH(Summary!I$6,'Balance Sheet'!$DE$5:$EB$5,0))} -> 78.862564 | J43: {=INDEX('Balance Sheet'!$DE$57:$EB$57,MATCH(Summary!J$6,'Balance Sheet'!$DE$5:$EB$5,0))} -> -148.84209 | K43: {=INDEX('Balance Sheet'!$DE$57:$EC$57,MATCH(Summary!K$6,'Balance Sheet'!$DE$5:$EC$5,0))} -> 135.34003
B44: Net Debt/EBITDA | C44: =C43/C31 -> 5.9849724 | D44: =D43/D31 -> 1.9118511 | E44: =E43/E31 -> 0.24956327 | F44: =F43/F31 -> -0.12250105 | G44: =G43/G31 -> 1.821716 | H44: =H43/H31 -> 0.83265094 | I44: =I43/I31 -> 0.19691438 | J44: =J43/J31 -> -0.33696408 | K44: =K43/K31 -> 0.29392994
B46: Total assets | C46: {=INDEX('Balance Sheet'!$25:$25,MATCH(Summary!C$6,'Balance Sheet'!$7:$7,0))} -> 521.74237 | D46: {=INDEX('Balance Sheet'!$25:$25,MATCH(Summary!D$6,'Balance Sheet'!$7:$7,0))} -> 543.75479 | E46: {=INDEX('Balance Sheet'!$25:$25,MATCH(Summary!E$6,'Balance Sheet'!$7:$7,0))} -> 750.99959 | F46: {=INDEX('Balance Sheet'!$25:$25,MATCH(Summary!F$6,'Balance Sheet'!$7:$7,0))} -> 1261.686 | G46: {=INDEX('Balance Sheet'!$25:$25,MATCH(Summary!G$6,'Balance Sheet'!$7:$7,0))} -> 1955.2133 | H46: {=INDEX('Balance Sheet'!$25:$25,MATCH(Summary!H$6,'Balance Sheet'!$7:$7,0))} -> 2122.2441 | I46: {=INDEX('Balance Sheet'!$25:$25,MATCH(Summary!I$6,'Balance Sheet'!$7:$7,0))} -> 2348.4629 | J46: {=INDEX('Balance Sheet'!$25:$25,MATCH(Summary!J$6,'Balance Sheet'!$7:$7,0))} -> 2528.2005 | K46: {=INDEX('Balance Sheet'!$25:$25,MATCH(Summary!K$6,'Balance Sheet'!$7:$7,0))} -> 2142.5371
B47: Current liabilities | C47: {=INDEX('Balance Sheet'!$34:$34,MATCH(Summary!C$6,'Balance Sheet'!$7:$7,0))} -> 10.952645 | D47: {=INDEX('Balance Sheet'!$34:$34,MATCH(Summary!D$6,'Balance Sheet'!$7:$7,0))} -> 23.547045 | E47: {=INDEX('Balance Sheet'!$34:$34,MATCH(Summary!E$6,'Balance Sheet'!$7:$7,0))} -> 68.284107 | F47: {=INDEX('Balance Sheet'!$34:$34,MATCH(Summary!F$6,'Balance Sheet'!$7:$7,0))} -> 92.592 | G47: {=INDEX('Balance Sheet'!$34:$34,MATCH(Summary!G$6,'Balance Sheet'!$7:$7,0))} -> 250.84664 | H47: {=INDEX('Balance Sheet'!$34:$34,MATCH(Summary!H$6,'Balance Sheet'!$7:$7,0))} -> 374.60037 | I47: {=INDEX('Balance Sheet'!$34:$34,MATCH(Summary!I$6,'Balance Sheet'!$7:$7,0))} -> 501.92933 | J47: {=INDEX('Balance Sheet'!$34:$34,MATCH(Summary!J$6,'Balance Sheet'!$7:$7,0))} -> 556.08893 | K47: {=INDEX('Balance Sheet'!$34:$34,MATCH(Summary!K$6,'Balance Sheet'!$7:$7,0))} -> 36.219
B48: ROCE | C48: =C16/(C46-C47) -> 0.0027029063 | D48: =D16/(D46-D47) -> 0.090712975 | E48: =E16/(E46-E47) -> 0.34078226 | F48: =F16/(F46-F47) -> 0.22678245 | G48: =G16/(G46-G47) -> 0.068120863 | H48: =H16/(H46-H47) -> 0.13135754 | I48: =I16/(I46-I47) -> 0.16013478 | J48: =J16/(J46-J47) -> 0.17084106 | K48: =K16/(K46-K47) -> 0.16885037
B49: Total debt | C49: {=INDEX('Balance Sheet'!$37:$37,MATCH(Summary!C$6,'Balance Sheet'!$7:$7,0))} -> 173.11224 | D49: {=INDEX('Balance Sheet'!$37:$37,MATCH(Summary!D$6,'Balance Sheet'!$7:$7,0))} -> 177.53899 | E49: {=INDEX('Balance Sheet'!$37:$37,MATCH(Summary!E$6,'Balance Sheet'!$7:$7,0))} -> 147.17383 | F49: {=INDEX('Balance Sheet'!$37:$37,MATCH(Summary!F$6,'Balance Sheet'!$7:$7,0))} -> 172.82 | G49: {=INDEX('Balance Sheet'!$37:$37,MATCH(Summary!G$6,'Balance Sheet'!$7:$7,0))} -> 431.043 | H49: =+Valuation!D12 -> 22 | I49: {=INDEX('Balance Sheet'!$37:$37,MATCH(Summary!I$6,'Balance Sheet'!$7:$7,0))} -> 367.043 | J49: {=INDEX('Balance Sheet'!$37:$37,MATCH(Summary!J$6,'Balance Sheet'!$7:$7,0))} -> 335.043 | K49: {=INDEX('Balance Sheet'!$37:$37,MATCH(Summary!K$6,'Balance Sheet'!$7:$7,0))} -> 303.043
B50: Equity | C50: {=INDEX('Balance Sheet'!$49:$49,MATCH(Summary!C$6,'Balance Sheet'!$7:$7,0))} -> 331.69405 | D50: {=INDEX('Balance Sheet'!$49:$49,MATCH(Summary!D$6,'Balance Sheet'!$7:$7,0))} -> 339.36464 | E50: {=INDEX('Balance Sheet'!$49:$49,MATCH(Summary!E$6,'Balance Sheet'!$7:$7,0))} -> 511.15966 | F50: {=INDEX('Balance Sheet'!$49:$49,MATCH(Summary!F$6,'Balance Sheet'!$7:$7,0))} -> 867.824 | G50: {=INDEX('Balance Sheet'!$49:$49,MATCH(Summary!G$6,'Balance Sheet'!$7:$7,0))} -> 1043.2296 | H50: {=INDEX('Balance Sheet'!$49:$49,MATCH(Summary!H$6,'Balance Sheet'!$7:$7,0))} -> 1118.5068 | I50: {=INDEX('Balance Sheet'!$49:$49,MATCH(Summary!I$6,'Balance Sheet'!$7:$7,0))} -> 1249.3966 | J50: {=INDEX('Balance Sheet'!$49:$49,MATCH(Summary!J$6,'Balance Sheet'!$7:$7,0))} -> 1406.9746 | K50: {=INDEX('Balance Sheet'!$49:$49,MATCH(Summary!K$6,'Balance Sheet'!$7:$7,0))} -> 1573.1811
B51: Tax rate | C51: {=INDEX('Income Statement'!$37:$37,MATCH(Summary!C$6,'Income Statement'!$7:$7,0))} -> -0.010558427 | D51: {=INDEX('Income Statement'!$37:$37,MATCH(Summary!D$6,'Income Statement'!$7:$7,0))} -> 0.02187502 | E51: {=INDEX('Income Statement'!$37:$37,MATCH(Summary!E$6,'Income Statement'!$7:$7,0))} -> 0.0093549995 | F51: {=INDEX('Income Statement'!$37:$37,MATCH(Summary!F$6,'Income Statement'!$7:$7,0))} -> 0.121681 | G51: {=INDEX('Income Statement'!$37:$37,MATCH(Summary!G$6,'Income Statement'!$7:$7,0))} -> 0.20030992 | H51: {=INDEX('Income Statement'!$37:$37,MATCH(Summary!H$6,'Income Statement'!$7:$7,0))} -> 0.21 | I51: {=INDEX('Income Statement'!$37:$37,MATCH(Summary!I$6,'Income Statement'!$7:$7,0))} -> 0.21 | J51: {=INDEX('Income Statement'!$37:$37,MATCH(Summary!J$6,'Income Statement'!$7:$7,0))} -> 0.21 | K51: {=INDEX('Income Statement'!$37:$37,MATCH(Summary!K$6,'Income Statement'!$7:$7,0))} -> 0.21
...

Sheet Valuation
B2: Atlas Energy Solutions
B3: Valuation
B4: (US$ Millions)
B6: Weighted Valution
B8: Methodology | C8: Weight | D8: Valuation
B9: Free Cash Flow Yield Method | C9: 0.5 | D9: =$H$28 -> 22.251094
B10: EV/EBITDA Method | C10: 0.5 | D10: =$H$59 -> 22.350853
B11: Discounted Cash Flow | C11: 0 | D11: =$H$79 -> 24.20378
B12: Weighted implied valuation | D12: =ROUND(AVERAGE(D9:D10),0.05) -> 22
B14: Current Price | D14: =+Summary!C120 -> 24.2
B15: Estimated return | D15: =D12/D14-1 -> -0.090909091
B16: Rating | D16: =IF(D15>0.15,"Buy",IF(D15<-0.15,"Sell","Neutral")) -> Neutral
B18: Free Cash Flow Yield Method
C20: 2025 | D20: =C20+1 -> 2026 | E20: =D20+1 -> 2027 | F20: =E20+1 -> 2028 | G20: =F20+1 -> 2029 | H20: =G20+1 -> 2030
B21: Free Cash Flow | C21: {=INDEX('Cash Flow'!$DF$58:$EF$58,MATCH(C$20,'Cash Flow'!$DF$7:$EF$7,0))} -> 248.46755 | D21: {=INDEX('Cash Flow'!$DF$58:$EF$58,MATCH(D$20,'Cash Flow'!$DF$7:$EF$7,0))} -> 317.11052 | E21: {=INDEX('Cash Flow'!$DF$58:$EF$58,MATCH(E$20,'Cash Flow'!$DF$7:$EF$7,0))} -> 351.14786 | F21: {=INDEX('Cash Flow'!$DF$58:$EF$58,MATCH(F$20,'Cash Flow'!$DF$7:$EF$7,0))} -> -154.56676 | G21: {=INDEX('Cash Flow'!$DF$58:$EF$58,MATCH(G$20,'Cash Flow'!$DF$7:$EF$7,0))} -> 933.87171 | H21: {=INDEX('Cash Flow'!$DF$58:$EM$58,MATCH(H$20,'Cash Flow'!$DF$7:$EM$7,0))} -> 406.14191
B22: Shares Outstanding | C22: {=INDEX('Income Statement'!$DU$59:$EF$59,MATCH(Valuation!C$20,'Income Statement'!$DU$7:$EF$7,0))} -> 111.078 | D22: {=INDEX('Income Statement'!$DU$59:$EF$59,MATCH(Valuation!D$20,'Income Statement'!$DU$7:$EF$7,0))} -> 111.078 | E22: {=INDEX('Income Statement'!$DU$59:$EF$59,MATCH(Valuation!E$20,'Income Statement'!$DU$7:$EF$7,0))} -> 111.078 | F22: {=INDEX('Income Statement'!$DU$59:$EF$59,MATCH(Valuation!F$20,'Income Statement'!$DU$7:$EF$7,0))} -> 111.078 | G22: {=INDEX('Income Statement'!$DU$59:$EF$59,MATCH(Valuation!G$20,'Income Statement'!$DU$7:$EF$7,0))} -> 111.078 | H22: {=INDEX('Income Statement'!$DU$59:$EM$59,MATCH(Valuation!H$20,'Income Statement'!$DU$7:$EM$7,0))} -> 111.078
B23: FCF/Share | C23: =C21/C22 -> 2.2368746 | D23: =D21/D22 -> 2.8548455 | E23: =E21/E22 -> 3.1612728 | F23: =F21/F22 -> -1.3915155 | G23: =G21/G22 -> 8.4073508 | H23: =H21/H22 -> 3.6563668
C24: =C23/$D$14 -> 0.092432833 | D24: =D23/$D$14 -> 0.11796882 | E24: =E23/$D$14 -> 0.13063111 | F24: =F23/$D$14 -> -0.05750064 | G24: =G23/$D$14 -> 0.34741119 | H24: =H23/$D$14 -> 0.15108954
B25: Historical FCF Yield
B26: Target FCF Yield | G26: 20 | H26: 0.15
B28: Implied Valuation | H28: =AVERAGE(D23:H23)/H26 -> 22.251094
B30: Current Price | H30: 24.2
B31: Estimated return | H31: =H28/H30-1 -> -0.080533317
B33: Enterprise Value to EBITDA Method
D34: 427 | E34: 604 | F34: 635
B35: Current Price Implied | C35: 2025 | D35: =D20 -> 2026 | E35: =E20 -> 2027 | F35: =F20 -> 2028 | G35: =G20 -> 2029 | H35: =H20 -> 2030 | J35: Target Price Implied | K35: =C35 -> 2025 | L35: =D35 -> 2026 | M35: =E35 -> 2027 | N35: =F35 -> 2028 | O35: =G35 -> 2029 | P35: =H35 -> 2030
B36: EBITDA | C36: {=INDEX('Income Statement'!$DU$47:$EF$47,MATCH(C$35,'Income Statement'!$DU$7:$EF$7,0))} -> 361.88657 | D36: {=INDEX('Income Statement'!$DU$47:$EF$47,MATCH(D$35,'Income Statement'!$DU$7:$EF$7,0))} -> 435.86073 | E36: {=INDEX('Income Statement'!$DU$47:$EF$47,MATCH(E$35,'Income Statement'!$DU$7:$EF$7,0))} -> 485.96772 | F36: {=INDEX('Income Statement'!$DU$47:$EF$47,MATCH(F$35,'Income Statement'!$DU$7:$EF$7,0))} -> 514.22921 | G36: {=INDEX('Income Statement'!$DU$47:$EF$47,MATCH(G$35,'Income Statement'!$DU$7:$EF$7,0))} -> 526.36271 | H36: {=INDEX('Income Statement'!$DU$47:$EM$47,MATCH(H$35,'Income Statement'!$DU$7:$EM$7,0))} -> 547.66709 | J36: =B36 -> EBITDA | K36: =C36 -> 361.88657 | L36: =D36 -> 435.86073 | M36: =E36 -> 485.96772 | N36: =F36 -> 514.22921 | O36: =G36 -> 526.36271 | P36: =H36 -> 547.66709
B37: Shares Outstanding | C37: {=INDEX('Income Statement'!$DU$59:$EF$59,MATCH(Valuation!C$35,'Income Statement'!$DU$7:$EF$7,0))} -> 111.078 | D37: {=INDEX('Income Statement'!$DU$59:$EF$59,MATCH(Valuation!D$35,'Income Statement'!$DU$7:$EF$7,0))} -> 111.078 | E37: {=INDEX('Income Statement'!$DU$59:$EF$59,MATCH(Valuation!E$35,'Income Statement'!$DU$7:$EF$7,0))} -> 111.078 | F37: {=INDEX('Income Statement'!$DU$59:$EF$59,MATCH(Valuation!F$35,'Income Statement'!$DU$7:$EF$7,0))} -> 111.078 | G37: {=INDEX('Income Statement'!$DU$59:$EF$59,MATCH(Valuation!G$35,'Income Statement'!$DU$7:$EF$7,0))} -> 111.078 | H37: {=INDEX('Income Statement'!$DU$59:$EM$59,MATCH(Valuation!H$35,'Income Statement'!$DU$7:$EM$7,0))} -> 111.078 | J37: =B37 -> Shares Outstanding | K37: =C37 -> 111.078 | L37: =D37 -> 111.078 | M37: =E37 -> 111.078 | N37: =F37 -> 111.078 | O37: =G37 -> 111.078 | P37: =H37 -> 111.078
B38: Current Price | C38: 18.33 | D38: =$H$30 -> 24.2 | E38: =$H$30 -> 24.2 | F38: =$H$30 -> 24.2 | G38: =$H$30 -> 24.2 | H38: =$H$30 -> 24.2 | J38: Target Price | K38: =$H$59 -> 22.350853 | L38: =$H$59 -> 22.350853 | M38: =$H$59 -> 22.350853 | N38: =$H$59 -> 22.350853 | O38: =$H$59 -> 22.350853 | P38: =$H$59 -> 22.350853
B39: Market Capitalization | C39: =C38*C37 -> 2036.0597 | D39: =D38*D37 -> 2688.0876 | E39: =E38*E37 -> 2688.0876 | F39: =F38*F37 -> 2688.0876 | G39: =G38*G37 -> 2688.0876 | H39: =H38*H37 -> 2688.0876 | J39: Implied Mkt Cap | K39: =K38*K37 -> 2482.6881 | L39: =L38*L37 -> 2482.6881 | M39: =M38*M37 -> 2482.6881 | N39: =N38*N37 -> 2482.6881 | O39: =O38*O37 -> 2482.6881 | P39: =P38*P37 -> 2482.6881
B40: Net Debt | C40: =172.82-210.174 -> -37.354 | D40: {=INDEX('Balance Sheet'!$DU$57:$EF$57,MATCH(Valuation!D$35,'Balance Sheet'!$DU$7:$EF$7,0))} -> 78.862564 | E40: {=INDEX('Balance Sheet'!$DU$57:$EF$57,MATCH(Valuation!E$35,'Balance Sheet'!$DU$7:$EF$7,0))} -> -148.84209 | F40: {=INDEX('Balance Sheet'!$DU$57:$EF$57,MATCH(Valuation!F$35,'Balance Sheet'!$DU$7:$EF$7,0))} -> 135.34003 | G40: {=INDEX('Balance Sheet'!$DU$57:$EF$57,MATCH(Valuation!G$35,'Balance Sheet'!$DU$7:$EF$7,0))} -> -662.43555 | H40: {=INDEX('Balance Sheet'!$DU$57:$EM$57,MATCH(Valuation!H$35,'Balance Sheet'!$DU$7:$EM$7,0))} -> -925.67652 | J40: =B40 -> Net Debt | K40: =C40 -> -37.354 | L40: =D40 -> 78.862564 | M40: =E40 -> -148.84209 | N40: =F40 -> 135.34003 | O40: =G40 -> -662.43555 | P40: =H40 -> -925.67652
B41: Preferred Equity | C41: 0 | D41: 0 | E41: 0 | F41: 0 | G41: 0 | H41: 0 | J41: =B41 -> Preferred Equity | K41: =C41 -> 0 | L41: =D41 -> 0 | M41: =E41 -> 0 | N41: =F41 -> 0 | O41: =G41 -> 0 | P41: =H41 -> 0
B42: Minority Interest | C42: 0 | D42: 0 | E42: 0 | F42: 0 | G42: 0 | H42: 0 | J42: =B42 -> Minority Interest | K42: =C42 -> 0 | L42: =D42 -> 0 | M42: =E42 -> 0 | N42: =F42 -> 0 | O42: =G42 -> 0 | P42: =H42 -> 0
B43: Enterprise Value | C43: =SUM(C39:C42) -> 1998.7057 | D43: =SUM(D39:D42) -> 2766.9502 | E43: =SUM(E39:E42) -> 2539.2455 | F43: =SUM(F39:F42) -> 2823.4276 | G43: =SUM(G39:G42) -> 2025.6521 | H43: =SUM(H39:H42) -> 1762.4111 | J43: =B43 -> Enterprise Value | K43: =SUM(K39:K42) -> 2445.3341 | L43: =SUM(L39:L42) -> 2561.5506 | M43: =SUM(M39:M42) -> 2333.846 | N43: =SUM(N39:N42) -> 2618.0281 | O43: =SUM(O39:O42) -> 1820.2525 | P43: =SUM(P39:P42) -> 1557.0115
B45: Implied EV/EBITDA | C45: =C43/C36 -> 5.5230171 | D45: =D43/D36 -> 6.3482438 | E45: =E43/E36 -> 5.225132 | F45: =F43/F36 -> 5.4906014 | G45: =G43/G36 -> 3.8483959 | H45: =H43/H36 -> 3.2180336 | J45: Implied EV/EBITDA | K45: =K43/K36 -> 6.7571838 | L45: =L43/L36 -> 5.8769934 | M45: =M43/M36 -> 4.8024712 | N45: =N43/N36 -> 5.0911696 | O45: =O43/O36 -> 3.4581715 | P45: =P43/P36 -> 2.8429891
B47: Through cycle EBITDA (2023-2026) | H47: =AVERAGE(D36:H36) -> 502.01749
B49: 2008-2014 average EV/EBITDA (Historical)
B50: Target through cycle EV/EBITDA | H50: 5.5
B52: Implied Enterprise Value | H52: =H50*H47 -> 2761.0962
B53: Net Debt | H53: {=INDEX('Balance Sheet'!$DU$57:$EB$57,MATCH(Valuation!C$35,'Balance Sheet'!$DU$7:$EB$7,0))} -> 278.40813
...

Sheet AESI_Live_Sheet
A1: Issuer: Atlas Energy Solutions | C1: 2500783373 | F1: 2020 | G1: 2021 | H1: 2022 | I1: 2023 | J1: 2024 | K1: 2025 | L1: 2026 | M1: 2027 | O1: 2020 Q1 | P1: 2020 Q2 | Q1: 2020 Q3 | R1: 2020 Q4 | S1: 2021 Q1 | T1: 2021 Q2 | U1: 2021 Q3 | V1: 2021 Q4 | W1: 2022 Q1 | X1: 2022 Q2 | Y1: 2022 Q3 | Z1: 2022 Q4 | AA1: 2023 Q1 | AB1: 2023 Q2 | AC1: 2023 Q3 | AD1: 2023 Q4 | AE1: 2024 Q1 | AF1: 2024 Q2 | AG1: 2024 Q3 | AH1: 2024 Q4 | AI1: 2025 Q1 | AJ1: 2025 Q2 | AK1: 2025 Q3 | AL1: 2025 Q4 | AM1: 2026 Q1 | AN1: 2026 Q2 | AO1: 2026 Q3 | AP1: 2026 Q4 | AQ1: 2027 Q1 | AR1: 2027 Q2 | AS1: 2027 Q3 | AT1: 2027 Q4
F2: Actual | G2: Actual | H2: Actual | I2: Actual | J2: Estimate | K2: Estimate | L2: Estimate | M2: Estimate | O2: Actual | P2: Actual | Q2: Actual | R2: Actual | S2: Actual | T2: Actual | U2: Actual | V2: Actual | W2: Actual | X2: Actual | Y2: Actual | Z2: Actual | AA2: Actual | AB2: Actual | AC2: Actual | AD2: Actual | AE2: Actual | AF2: Actual | AG2: Actual | AH2: Estimate | AI2: Estimate | AJ2: Estimate | AK2: Estimate | AL2: Estimate | AM2: Estimate | AN2: Estimate | AO2: Estimate | AP2: Estimate | AQ2: Estimate | AR2: Estimate | AS2: Estimate | AT2: Estimate
F3: 44196 | G3: 44561 | H3: 44926 | I3: 45291 | J3: 45657 | K3: 46022 | L3: 46387 | M3: 46752 | O3: 43921 | P3: 44012 | Q3: 44104 | R3: 44196 | S3: 44286 | T3: 44377 | U3: 44469 | V3: 44561 | W3: 44651 | X3: 44742 | Y3: 44834 | Z3: 44926 | AA3: 45016 | AB3: 45107 | AC3: 45199 | AD3: 45291 | AE3: 45382 | AF3: 45473 | AG3: 45565 | AH3: 45657 | AI3: 45747 | AJ3: 45838 | AK3: 45930 | AL3: 46022 | AM3: 46112 | AN3: 46203 | AO3: 46295 | AP3: 46387 | AQ3: 46477 | AR3: 46568 | AS3: 46660 | AT3: 46752
A4: Issuer: Atlas Energy Solutions | B4: 1510B3H
A5: Reference Data
B6: Issuer Name | C6: Issuer Name | E6: Atlas Energy Solutions
B7: Reporting Currency | C7: CURRENCY_ISO | E7: USD
A8: General Information
B9: M&A probability (1 = high, 3 = low) | C9: MA_PROB | E9: 3
A10: Income Statement
B11: Sales, net revenue | C11: SALES | D11: =AESI_Live_Sheet!L_CURRENCY_ISSR_208021701_REP -> USD | F11: 111.77163 | G11: 172.40566 | H11: 482.59377 | I11: 613.96 | J11: 1063.6907 | K11: 1321.3546 | L11: 1357.5616 | M11: 1409.0723 | O11: 42.722146 | P11: 13.737979 | Q11: 28.992068 | R11: 26.319435 | S11: 31.831894 | T11: 44.428787 | U11: 43.297373 | V11: 52.847608 | W11: 59.853818 | X11: 131.32338 | Y11: 141.55213 | Z11: 149.86444 | AA11: 153.418 | AB11: 161.788 | AC11: 157.616 | AD11: 141.138 | AE11: 192.667 | AF11: 287.518 | AG11: 304.434 | AH11: 279.07171 | AI11: 314.47631 | AJ11: 330.92099 | AK11: 337.31654 | AL11: 338.64074 | AM11: 332.0986 | AN11: 337.02854 | AO11: 342.77966 | AP11: 345.65478 | AQ11: 348.0172 | AR11: 351.09643 | AS11: 354.20298 | AT11: 355.75565
B12: Cost of goods sold, COGS | C12: COST_GD_SD | D12: =AESI_Live_Sheet!L_CURRENCY_ISSR_208021701_REP -> USD | F12: -73.118 | G12: -84.656 | H12: -198.96207 | I12: -260.396 | J12: -738.68196 | K12: -882.64942 | L12: -862.04063 | M12: -868.7222 | O12: -18.2795 | P12: -18.2795 | Q12: -18.2795 | R12: -18.2795 | S12: -18.92 | T12: -21.912 | U12: -21.912 | V12: -21.912 | W12: -24.494075 | X12: -47.044394 | Y12: -60.138574 | Z12: -67.285024 | AA12: -62.555 | AB12: -63.504 | AC12: -67.77 | AD12: -66.567 | AE12: -106.746 | AF12: -202.136 | AG12: -225.347 | AH12: -204.45296 | AI12: -223.40134 | AJ12: -218.47626 | AK12: -220.32899 | AL12: -220.44283 | AM12: -212.67077 | AN12: -214.91263 | AO12: -217.0316 | AP12: -217.42563 | AQ12: -215.76729 | AR12: -216.92247 | AS12: -218.00239 | AT12: -218.03005
B13: SG&A, selling, general and admin. expense | C13: SEL_GL_AD | D13: =AESI_Live_Sheet!L_CURRENCY_ISSR_208021701_REP -> USD | F13: -14.506318 | G13: -16.019176 | H13: -22.520389 | I13: -48.636 | J13: -101.33302 | K13: -92.494821 | L13: -95.02931 | M13: -98.635058 | O13: -4.0907364 | P13: -2.4430765 | Q13: -3.4044525 | R13: -4.5680524 | S13: -3.9740135 | T13: -3.7569652 | U13: -3.5100979 | V13: -4.778099 | W13: -4.7567287 | X13: -4.843585 | Y13: -5.4519953 | Z13: -7.4680798 | AA13: -8.504 | AB13: -12.183 | AC13: -14.301 | AD13: -13.648 | AE13: -29.069 | AF13: -27.266 | AG13: -25.463 | AH13: -19.53502 | AI13: -22.013342 | AJ13: -23.164469 | AK13: -23.612158 | AL13: -23.704852 | AM13: -23.246902 | AN13: -23.591998 | AO13: -23.994576 | AP13: -24.195835 | AQ13: -24.361204 | AR13: -24.57675 | AS13: -24.794209 | AT13: -24.902895
B14: Total operating expense | C14: OP_COST | D14: =AESI_Live_Sheet!L_CURRENCY_ISSR_208021701_REP -> USD | F14: -87.624318 | G14: -100.67518 | H14: -221.48246 | I14: -309.032 | J14: -840.01498 | K14: -975.14424 | L14: -957.06994 | M14: -967.35725 | O14: -22.370236 | P14: -20.722577 | Q14: -21.683952 | R14: -22.847552 | S14: -22.894014 | T14: -25.668965 | U14: -25.422098 | V14: -26.690099 | W14: -29.250804 | X14: -51.887979 | Y14: -65.59057 | Z14: -74.753104 | AA14: -71.059 | AB14: -75.687 | AC14: -82.071 | AD14: -80.215 | AE14: -135.815 | AF14: -229.402 | AG14: -250.81 | AH14: -223.98798 | AI14: -245.41468 | AJ14: -241.64073 | AK14: -243.94114 | AL14: -244.14768 | AM14: -235.91768 | AN14: -238.50463 | AO14: -241.02617 | AP14: -241.62146 | AQ14: -240.12849 | AR14: -241.49922 | AS14: -242.7966 | AT14: -242.93295
B15: R&D expense | C15: RD_EXP | D15: =AESI_Live_Sheet!L_CURRENCY_ISSR_208021701_REP -> USD
B16: ESO expense (pre-tax) | C16: ESO_PRE_TAX | D16: =AESI_Live_Sheet!L_CURRENCY_ISSR_208021701_REP -> USD
B17: Other operating income/(expense) (incl. leases) | C17: OTH_OP_INC_EXP | D17: =AESI_Live_Sheet!L_CURRENCY_ISSR_208021701_REP -> USD
B18: Total operating expense (incl. D&A) | C18: TOT_OPS_EXP_DDA | D18: =AESI_Live_Sheet!L_CURRENCY_ISSR_208021701_REP -> USD | F18: -109.14101 | G18: -125.21607 | H18: -249.93645 | I18: -348.83 | J18: -934.48533 | K18: -1079.9416 | L18: -1061.8673 | M18: -1072.1546 | O18: -27.987938 | P18: -25.429196 | Q18: -27.15319 | R18: -28.570688 | S18: -28.575479 | T18: -31.834319 | U18: -31.597161 | V18: -33.20911 | W18: -35.715276 | X18: -58.619829 | Y18: -72.87123 | Z18: -82.730112 | AA18: -79.578 | AB18: -85.12 | AC18: -92.292 | AD18: -91.84 | AE18: -152.99 | AF18: -254.429 | AG18: -276.879 | AH18: -250.18733 | AI18: -271.61403 | AJ18: -267.84007 | AK18: -270.14049 | AL18: -270.34703 | AM18: -262.11702 | AN18: -264.70397 | AO18: -267.22552 | AP18: -267.82081 | AQ18: -266.32784 | AR18: -267.69856 | AS18: -268.99594 | AT18: -269.13229
B19: Total operating expense (excl. D&A) | C19: TOT_OPS_EXP | D19: =AESI_Live_Sheet!L_CURRENCY_ISSR_208021701_REP -> USD | F19: -87.624318 | G19: -100.67518 | H19: -221.48246 | I19: -309.032 | J19: -840.01498 | K19: -975.14424 | L19: -957.06994 | M19: -967.35725 | O19: -22.370236 | P19: -20.722577 | Q19: -21.683952 | R19: -22.847552 | S19: -22.894014 | T19: -25.668965 | U19: -25.422098 | V19: -26.690099 | W19: -29.250804 | X19: -51.887979 | Y19: -65.59057 | Z19: -74.753104 | AA19: -71.059 | AB19: -75.687 | AC19: -82.071 | AD19: -80.215 | AE19: -135.815 | AF19: -229.402 | AG19: -250.81 | AH19: -223.98798 | AI19: -245.41468 | AJ19: -241.64073 | AK19: -243.94114 | AL19: -244.14768 | AM19: -235.91768 | AN19: -238.50463 | AO19: -241.02617 | AP19: -241.62146 | AQ19: -240.12849 | AR19: -241.49922 | AS19: -242.7966 | AT19: -242.93295
B20: EBITDA | C20: EBITDA_CALC | D20: =AESI_Live_Sheet!L_CURRENCY_ISSR_208021701_REP -> USD | F20: 22.897311 | G20: 71.730486 | H20: 261.11132 | I20: 321.963 | J20: 288.02169 | K20: 373.909 | L20: 436.16541 | M20: 486.27241 | O20: 20.03941 | P20: -7.2970977 | Q20: 6.995616 | R20: 3.1593829 | S20: 8.9378806 | T20: 18.759821 | U20: 17.875275 | V20: 26.157509 | W20: 30.603014 | X20: 79.435402 | Y20: 75.961561 | Z20: 75.11134 | AA20: 82.359 | AB20: 86.101 | AC20: 75.545 | AD20: 68.706 | AE20: 75.543 | AF20: 79.072 | AG20: 71.051 | AH20: 62.355694 | AI20: 76.023014 | AJ20: 95.815313 | AK20: 100.0135 | AL20: 102.05718 | AM20: 104.50677 | AN20: 107.12014 | AO20: 110.92412 | AP20: 113.61439 | AQ20: 118.30888 | AR20: 120.54486 | AS20: 122.81556 | AT20: 124.6031
B21: Depreciation | C21: DEPREC | D21: =AESI_Live_Sheet!L_CURRENCY_ISSR_208021701_REP -> USD | F21: -21.516694 | G21: -24.540894 | H21: -28.453991 | I21: -39.798 | J21: -94.470345 | K21: -104.79738 | L21: -104.79738 | M21: -104.79738 | O21: -5.6177018 | P21: -4.7066194 | Q21: -5.4692377 | R21: -5.7231352 | S21: -5.6814658 | T21: -6.1653538 | U21: -6.1750633 | V21: -6.5190106 | W21: -6.4644721 | X21: -6.7318501 | Y21: -7.2806603 | Z21: -7.9770085 | AA21: -8.519 | AB21: -9.433 | AC21: -10.221 | AD21: -11.625 | AE21: -17.175 | AF21: -25.027 | AG21: -26.069 | AH21: -26.199345 | AI21: -26.199345 | AJ21: -26.199345 | AK21: -26.199345 | AL21: -26.199345 | AM21: -26.199345 | AN21: -26.199345 | AO21: -26.199345 | AP21: -26.199345 | AQ21: -26.199345 | AR21: -26.199345 | AS21: -26.199345 | AT21: -26.199345
B22: Amortization | C22: GOODWILL_AMORT | D22: =AESI_Live_Sheet!L_CURRENCY_ISSR_208021701_REP -> USD
B23: EBIT, operating profit | C23: EBIT | D23: =AESI_Live_Sheet!L_CURRENCY_ISSR_208021701_REP -> USD | F23: 2.6306168 | G23: 47.189592 | H23: 232.65733 | I23: 265.13 | J23: 129.20539 | K23: 241.41297 | L23: 295.69426 | M23: 336.91763 | O23: 14.734208 | P23: -11.691217 | Q23: 1.8388783 | R23: -2.2512523 | S23: 3.2564148 | T23: 12.594468 | U23: 11.700211 | V23: 19.638499 | W23: 24.138542 | X23: 72.703552 | Y23: 68.680901 | Z23: 67.134332 | AA23: 73.84 | AB23: 76.668 | AC23: 65.324 | AD23: 49.298 | AE23: 39.677 | AF23: 33.089 | AG23: 27.555 | AH23: 28.884387 | AI23: 42.86228 | AJ23: 63.080917 | AK23: 67.176055 | AL23: 68.293717 | AM23: 69.981576 | AN23: 72.324562 | AO23: 75.554144 | AP23: 77.833974 | AQ23: 81.689367 | AR23: 83.397864 | AS23: 85.207038 | AT23: 86.623357
B24: Interest income | C24: INT_INC_IND | D24: =AESI_Live_Sheet!L_CURRENCY_ISSR_208021701_REP -> USD
B25: Interest expense | C25: INT_EXP_IND | D25: =AESI_Live_Sheet!L_CURRENCY_ISSR_208021701_REP -> USD | F25: -32.819165 | G25: -30.276282 | H25: -15.739831 | I25: -7.689 | J25: -37.822 | K25: -24.391786 | L25: -13.037606 | M25: -13.037606 | O25: -7.5915417 | P25: -8.0636007 | Q25: -8.4732294 | R25: -8.6907927 | S25: -8.4997901 | T25: -8.5120422 | U25: -8.2526235 | V25: -5.0118261 | W25: -3.9897278 | X25: -3.8835333 | Y25: -3.8762648 | Z25: -3.9903049 | AA25: -3.442 | AB25: -0.521 | AC25: -1.496 | AD25: -2.23 | AE25: -4.978 | AF25: -10.458 | AG25: -11.193 | AH25: -11.193 | AI25: -8.9544 | AJ25: -7.16352 | AK25: -5.014464 | AL25: -3.2594016 | AM25: -3.2594016 | AN25: -3.2594016 | AO25: -3.2594016 | AP25: -3.2594016 | AQ25: -3.2594016 | AR25: -3.2594016 | AS25: -3.2594016 | AT25: -3.2594016
B26: Net interest income/(expense) | C26: NET_INT_EXP | D26: =AESI_Live_Sheet!L_CURRENCY_ISSR_208021701_REP -> USD | F26: -32.819165 | G26: -30.276282 | H26: -15.739831 | I26: -7.689 | J26: -37.822 | K26: -24.391786 | L26: -13.037606 | M26: -13.037606 | O26: -7.5915417 | P26: -8.0636007 | Q26: -8.4732294 | R26: -8.6907927 | S26: -8.4997901 | T26: -8.5120422 | U26: -8.2526235 | V26: -5.0118261 | W26: -3.9897278 | X26: -3.8835333 | Y26: -3.8762648 | Z26: -3.9903049 | AA26: -3.442 | AB26: -0.521 | AC26: -1.496 | AD26: -2.23 | AE26: -4.978 | AF26: -10.458 | AG26: -11.193 | AH26: -11.193 | AI26: -8.9544 | AJ26: -7.16352 | AK26: -5.014464 | AL26: -3.2594016 | AM26: -3.2594016 | AN26: -3.2594016 | AO26: -3.2594016 | AP26: -3.2594016 | AQ26: -3.2594016 | AR26: -3.2594016 | AS26: -3.2594016 | AT26: -3.2594016
B27: Income/(loss) from unconsolidated subs & associates | C27: ASSOCIATE | D27: =AESI_Live_Sheet!L_CURRENCY_ISSR_208021701_REP -> USD
B28: Profit/(loss) on disposals of assets, pre-tax | C28: PROFIT_ON_DISP | D28: =AESI_Live_Sheet!L_CURRENCY_ISSR_208021701_REP -> USD
B29: Other non-ops income/(expense) | C29: OTH_COST_INC | D29: =AESI_Live_Sheet!L_CURRENCY_ISSR_208021701_REP -> USD | F29: -5.1314379 | G29: 4.5908677 | I29: 0.43 | J29: -16.734 | O29: -1.3893248 | P29: -2.4962639 | Q29: -0.43985546 | R29: -0.80599374 | S29: 0.01130557 | T29: 4.4923336 | U29: 0.03033345 | V29: 0.056895 | AA29: 0.184 | AB29: 0.118 | AC29: 0.136 | AD29: -0.008 | AE29: 0.023 | AF29: 5.004 | AG29: 12.607
B30: Pre-tax profit | C30: PT_PROF | D30: =AESI_Live_Sheet!L_CURRENCY_ISSR_208021701_REP -> USD | F30: -35.319986 | G30: 21.504178 | H30: 216.9175 | I30: 257.871 | J30: 74.649387 | K30: 217.02118 | L30: 282.65665 | M30: 323.88002 | O30: 5.7533413 | P30: -22.251082 | Q30: -7.0742065 | R30: -11.748039 | S30: -5.2320697 | T30: 8.5747592 | U30: 3.4779213 | V30: 14.683567 | W30: 20.148815 | X30: 68.820018 | Y30: 64.804636 | Z30: 63.144027 | AA30: 70.582 | AB30: 76.265 | AC30: 63.964 | AD30: 47.06 | AE30: 34.722 | AF30: 17.903 | AG30: 4.333 | AH30: 17.691387 | AI30: 33.90788 | AJ30: 55.917397 | AK30: 62.161591 | AL30: 65.034315 | AM30: 66.722174 | AN30: 69.065161 | AO30: 72.294742 | AP30: 74.574572 | AQ30: 78.429965 | AR30: 80.138462 | AS30: 81.947636 | AT30: 83.363956
A31: Additional Income Statement Items
B32: Operating lease cost | C32: LEASE_PAY | D32: =AESI_Live_Sheet!L_CURRENCY_ISSR_208021701_REP -> USD
B33: Lease payments (deemed interest portion) | C33: LEASE_DEEM_INT | D33: =AESI_Live_Sheet!L_CURRENCY_ISSR_208021701_REP -> USD
B34: Lease payments (deemed depreciation portion) | C34: LEASE_DEEM_DEPR | D34: =AESI_Live_Sheet!L_CURRENCY_ISSR_208021701_REP -> USD
B35: Gross interest charge | C35: NET_INT_CH | D35: =AESI_Live_Sheet!L_CURRENCY_ISSR_208021701_REP -> USD
B36: Income from associates (operating) | C36: ASSOCIATE_OP | D36: =AESI_Live_Sheet!L_CURRENCY_ISSR_208021701_REP -> USD
B37: Depreciation ROU assets (applicable to IFRS cos.) | C37: DEPR_ROU_ASSETS | D37: =AESI_Live_Sheet!L_CURRENCY_ISSR_208021701_REP -> USD
B38: Lease interest charge (applicable to IFRS cos.) | C38: LEASE_INT_CHG | D38: =AESI_Live_Sheet!L_CURRENCY_ISSR_208021701_REP -> USD
B39: Lease standard adopted (US GAAP ASC 842/ IFRS 16) | C39: LEASE_ADOPT | E39: Y
A40: Balance Sheet
...

Sheet AESI_Validation_Sheet
A1: d50ffbf1-b4f1-40f2-ab05-0ee809f33152
A2: =CELL("filename",AESI_Validation_Sheet!$A2) -> H:\[testModel.xlsx]AESI_Validation_Sheet
A3: =_xll.Exchange.Rtd.QVS(AESI_Validation_Sheet!$A1,AESI_Validation_Sheet!$A2,#REF!,AESI_Annotation_Sheet!B2:AT315,AESI_Live_Sheet!B2:AT315) -> #NAME?
A7: Scalar|||208021701|||ISSR|||CURRENCY_ISO|||False||| | C7: V_KEYWORD_ISSR_208021701_CURRENCY_ISO
A9: Scalar|||208021701|||ISSR|||MA_PROB|||False||| | C9: V_KEYWORD_ISSR_208021701_MA_PROB
A11: Vector|||208021701|||ISSR|||SALES|||False||| | C11: V_KEYWORD_ISSR_208021701_SALES
A12: Vector|||208021701|||ISSR|||COST_GD_SD|||False||| | C12: V_KEYWORD_ISSR_208021701_COST_GD_SD
A13: Vector|||208021701|||ISSR|||SEL_GL_AD|||False||| | C13: V_KEYWORD_ISSR_208021701_SEL_GL_AD
A14: Vector|||208021701|||ISSR|||OP_COST|||False||| | C14: V_KEYWORD_ISSR_208021701_OP_COST
A15: Vector|||208021701|||ISSR|||RD_EXP|||False||| | C15: V_KEYWORD_ISSR_208021701_RD_EXP
A16: Vector|||208021701|||ISSR|||ESO_PRE_TAX|||False||| | C16: V_KEYWORD_ISSR_208021701_ESO_PRE_TAX
A17: Vector|||208021701|||ISSR|||OTH_OP_INC_EXP|||False||| | C17: V_KEYWORD_ISSR_208021701_OTH_OP_INC_EXP
A18: Vector|||208021701|||ISSR|||TOT_OPS_EXP_DDA|||False||| | C18: V_KEYWORD_ISSR_208021701_TOT_OPS_EXP_DDA
A19: Vector|||208021701|||ISSR|||TOT_OPS_EXP|||False||| | C19: V_KEYWORD_ISSR_208021701_TOT_OPS_EXP
A20: Vector|||208021701|||ISSR|||EBITDA_CALC|||False||| | C20: V_KEYWORD_ISSR_208021701_EBITDA_CALC
... A315: Scalar|||200022132|||EQTY|||RISK_FR_RATE|||False||| | C315: V_KEYWORD_EQTY_200022132_RISK_FR_RATE

Sheet AESI_Annotation_Sheet
A1: Issuer: Atlas Energy Solutions | F1: 2020 | G1: 2021 | H1: 2022 | I1: 2023 | J1: 2024 | K1: 2025 | L1: 2026 | M1: 2027 | O1: 2020 Q1 | P1: 2020 Q2 | Q1: 2020 Q3 | R1: 2020 Q4 | S1: 2021 Q1 | T1: 2021 Q2 | U1: 2021 Q3 | V1: 2021 Q4 | W1: 2022 Q1 | X1: 2022 Q2 | Y1: 2022 Q3 | Z1: 2022 Q4 | AA1: 2023 Q1 | AB1: 2023 Q2 | AC1: 2023 Q3 | AD1: 2023 Q4 | AE1: 2024 Q1 | AF1: 2024 Q2 | AG1: 2024 Q3 | AH1: 2024 Q4 | AI1: 2025 Q1 | AJ1: 2025 Q2 | AK1: 2025 Q3 | AL1: 2025 Q4 | AM1: 2026 Q1 | AN1: 2026 Q2 | AO1: 2026 Q3 | AP1: 2026 Q4 | AQ1: 2027 Q1 | AR1: 2027 Q2 | AS1: 2027 Q3 | AT1: 2027 Q4
A4: Issuer: Atlas Energy Solutions
A5: Reference Data
B6: Issuer Name | C6: Issuer Name | E6: Atlas Energy Solutions
B7: Reporting Currency | C7: CURRENCY_ISO | E7: USD
A8: General Information
B9: M&A probability (1 = high, 3 = low) | C9: MA_PROB
A10: Income Statement
B11: Sales, net revenue | C11: SALES | D11: =E_CURRENCY_ISSR_208021701_REP -> #NAME?
B12: Cost of goods sold, COGS | C12: COST_GD_SD | D12: =E_CURRENCY_ISSR_208021701_REP -> #NAME?
B13: SG&A, selling, general and admin. expense | C13: SEL_GL_AD | D13: =E_CURRENCY_ISSR_208021701_REP -> #NAME?
B14: Total operating expense | C14: OP_COST | D14: =E_CURRENCY_ISSR_208021701_REP -> #NAME?
B15: R&D expense | C15: RD_EXP | D15: =E_CURRENCY_ISSR_208021701_REP -> #NAME?
B16: ESO expense (pre-tax) | C16: ESO_PRE_TAX | D16: =E_CURRENCY_ISSR_208021701_REP -> #NAME?
B17: Other operating income/(expense) (incl. leases) | C17: OTH_OP_INC_EXP | D17: =E_CURRENCY_ISSR_208021701_REP -> #NAME?
B18: Total operating expense (incl. D&A) | C18: TOT_OPS_EXP_DDA | D18: =E_CURRENCY_ISSR_208021701_REP -> #NAME?
B19: Total operating expense (excl. D&A) | C19: TOT_OPS_EXP | D19: =E_CURRENCY_ISSR_208021701_REP -> #NAME?
B20: EBITDA | C20: EBITDA_CALC | D20: =E_CURRENCY_ISSR_208021701_REP -> #NAME?
B21: Depreciation | C21: DEPREC | D21: =E_CURRENCY_ISSR_208021701_REP -> #NAME?
B22: Amortization | C22: GOODWILL_AMORT | D22: =E_CURRENCY_ISSR_208021701_REP -> #NAME?
... B30: Pre-tax profit | C30: PT_PROF | D30: =E_CURRENCY_ISSR_208021701_REP -> #NAME?
A31: Additional Income Statement Items
B32: Operating lease cost | C32: LEASE_PAY | D32: =E_CURRENCY_ISSR_208021701_REP -> #NAME?
B33: Lease payments (deemed interest portion) | C33: LEASE_DEEM_INT | D33: =E_CURRENCY_ISSR_208021701_REP -> #NAME?
B34: Lease payments (deemed depreciation portion) | C34: LEASE_DEEM_DEPR | D34: =E_CURRENCY_ISSR_208021701_REP -> #NAME?
B35: Gross interest charge | C35: NET_INT_CH | D35: =E_CURRENCY_ISSR_208021701_REP -> #NAME?
B36: Income from associates (operating) | C36: ASSOCIATE_OP | D36: =E_CURRENCY_ISSR_208021701_REP -> #NAME?
B37: Depreciation ROU assets (applicable to IFRS cos.) | C37: DEPR_ROU_ASSETS | D37: =E_CURRENCY_ISSR_208021701_REP -> #NAME?
B38: Lease interest charge (applicable to IFRS cos.) | C38: LEASE_INT_CHG | D38: =E_CURRENCY_ISSR_208021701_REP -> #NAME?
B39: Lease standard adopted (US GAAP ASC 842/ IFRS 16) | C39: LEASE_ADOPT
A40: Balance Sheet
B41: Cash & cash equivalents | C41: CASH_EQ | D41: =E_CURRENCY_ISSR_208021701_REP -> #NAME?
B42: Accounts receivable | C42: DEBTORS | D42: =E_CURRENCY_ISSR_208021701_REP -> #NAME?
B43: Inventory | C43: STOCKS | D43: =E_CURRENCY_ISSR_208021701_REP -> #NAME?
B44: Other current assets | C44: OTH_CUR_ASS | D44: =E_CURRENCY_ISSR_208021701_REP -> #NAME?
B45: Total current assets | C45: CUR_ASS | D45: =E_CURRENCY_ISSR_208021701_REP -> #NAME?
B46: Gross fixed assets, PP&E | C46: GR_FIX_ASS | D46: =E_CURRENCY_ISSR_208021701_REP -> #NAME?
B47: Accumulated depreciation | C47: ACC_DDA | D47: =E_CURRENCY_ISSR_208021701_REP -> #NAME?
B48: Net PP&E | C48: NET_FIX_ASS | D48: =E_CURRENCY_ISSR_208021701_REP -> #NAME?
B49: Gross intangibles | C49: GR_INTANG | D49: =E_CURRENCY_ISSR_208021701_REP -> #NAME?
...

Sheet Income Statement
A2: x | B2: Atlas Energy Solutions Limited
B3: Income Statement
B4: (US$ Millions)
